Workbook

Sheet 영수증 내역
A1: 영수증 정리 (2025-07 ~ 2026-09)
A2: 합계는 "합계반영=Y" 이고 통화=CAD 인 건만 집계 (중복 사진·카드전표는 N). 미국(USD) 2건은 별도.
A3: CAD 합계 | I3: =SUMIFS(I6:I164,O6:O164,"Y",H6:H164,"CAD") | J3: =SUMIFS(J6:J164,O6:O164,"Y",H6:H164,"CAD") | K3: =SUMIFS(K6:K164,O6:O164,"Y",H6:H164,"CAD") | L3: =SUMIFS(L6:L164,O6:O164,"Y",H6:H164,"CAD") | M3: =SUMIFS(M6:M164,O6:O164,"Y",H6:H164,"CAD") | N3: =COUNTIFS(O6:O164,"Y",H6:H164,"CAD")&"건"
I4: 소계(세전) | J4: HST | K4: 기타세금 | L4: 팁 | M4: 합계
A5: No | B5: 날짜 | C5: 연월 | D5: 시간 | E5: 구입처 | F5: 구입처 그룹 | G5: 위치/주소 | H5: 통화 | I5: 소계(세전) | J5: HST | K5: 기타세금 | L5: 팁 | M5: 합계(총결제액) | N5: 결제수단 | O5: 합계반영 | P5: 비고 | Q5: 원본 파일
A6: 1 | B6: 45668 | C6: =IF(B6="","미기재",TEXT(B6,"yyyy-mm")) | D6: 16:53 | E6: Chick-fil-A | F6: Chick-fil-A | G6: Toronto Eaton Centre, Toronto | H6: CAD | I6: 7.39 | J6: 0.96 | M6: 8.35 | N6: Credit | O6: Y | P6: 확인 필요: 영수증 날짜 01/11/2025 → 미국식(MM/DD)으로 2025-01-11 처리. 일/월 순서면 2025-11-01 | Q6: IMG_5351.HEIC
A7: 2 | B7: 45853 | C7: =IF(B7="","미기재",TEXT(B7,"yyyy-mm")) | D7: 06:08 | E7: Etobicoke Olympium (FitnessTO) | F7: Etobicoke Olympium (FitnessTO) | G7: 590 Rathburn Rd, Toronto | H7: CAD | I7: 2.16 | J7: 0.28 | M7: 2.44 | N7: Visa | O7: Y | P7: 드롭인(Youth) | Q7: IMG_5596.HEIC
A8: 3 | B8: 45854 | C8: =IF(B8="","미기재",TEXT(B8,"yyyy-mm")) | D8: 06:12 | E8: Etobicoke Olympium (FitnessTO) | F8: Etobicoke Olympium (FitnessTO) | G8: 590 Rathburn Rd, Toronto | H8: CAD | I8: 2.16 | J8: 0.28 | M8: 2.44 | N8: Visa | O8: Y | P8: 드롭인 | Q8: IMG_5593.HEIC
A9: 4 | B9: 45855 | C9: =IF(B9="","미기재",TEXT(B9,"yyyy-mm")) | D9: 06:10 | E9: Etobicoke Olympium (FitnessTO) | F9: Etobicoke Olympium (FitnessTO) | G9: 590 Rathburn Rd, Toronto | H9: CAD | I9: 2.16 | J9: 0.28 | M9: 2.44 | N9: Visa | O9: Y | P9: 드롭인(Youth) | Q9: IMG_5595.HEIC
A10: 5 | B10: 45859 | C10: =IF(B10="","미기재",TEXT(B10,"yyyy-mm")) | D10: 06:51 | E10: Etobicoke Olympium (FitnessTO) | F10: Etobicoke Olympium (FitnessTO) | G10: 590 Rathburn Rd, Toronto | H10: CAD | I10: 2.16 | J10: 0.28 | M10: 2.44 | N10: Visa | O10: Y | P10: 드롭인 | Q10: IMG_5594.HEIC
A11: 6 | B11: 45884 | C11: =IF(B11="","미기재",TEXT(B11,"yyyy-mm")) | D11: 06:12 | E11: Etobicoke Olympium (FitnessTO) | F11: Etobicoke Olympium (FitnessTO) | G11: 590 Rathburn Rd, Toronto | H11: CAD | I11: 38.78 | J11: 5.04 | M11: 43.82 | N11: Visa | O11: Y | P11: 수영 멤버십 1개월(Adult) | Q11: IMG_5591.HEIC
A12: 7 | B12: 45884 | C12: =IF(B12="","미기재",TEXT(B12,"yyyy-mm")) | D12: 06:13 | E12: Etobicoke Olympium (FitnessTO) | F12: Etobicoke Olympium (FitnessTO) | G12: 590 Rathburn Rd, Toronto | H12: CAD | I12: 19.39 | J12: 2.52 | M12: 21.91 | N12: Visa | O12: Y | P12: 수영 멤버십 1개월(Youth) | Q12: IMG_5590.HEIC
A13: 8 | B13: 45884 | C13: =IF(B13="","미기재",TEXT(B13,"yyyy-mm")) | D13: 06:14 | E13: Etobicoke Olympium (FitnessTO) | F13: Etobicoke Olympium (FitnessTO) | G13: 590 Rathburn Rd, Toronto | H13: CAD | I13: 16.53 | J13: 2.15 | M13: 18.68 | N13: Visa | O13: Y | P13: 멤버십 1개월(Youth) | Q13: IMG_5597.HEIC
A14: 9 | B14: 45902 | C14: =IF(B14="","미기재",TEXT(B14,"yyyy-mm")) | D14: 13:46 | E14: Home Depot (North Queen) | F14: Home Depot | G14: 193 N Queen St, Etobicoke | H14: CAD | I14: 2147.48 | J14: 279.18 | M14: 2426.66 | N14: Mastercard | O14: Y | P14: 가전(GE Profile) 주문 + 부품 / 10% 할인 -218.80 / 배송 2025-09-10 | Q14: IMG_5651.HEIC
A15: 10 | B15: 45904 | C15: =IF(B15="","미기재",TEXT(B15,"yyyy-mm")) | D15: 12:43 | E15: SushiOne x Jjajang1980 | F15: SushiOne x Jjajang1980 | G15: 4924 Yonge St, North York | H15: CAD | I15: 40.49 | J15: 5.26 | M15: 45.75 | N15: Cash | O15: Y | P15: 소계 44.99에서 현금할인 10% -4.50 적용 | Q15: IMG_5531.HEIC
A16: 11 | B16: 45906 | C16: =IF(B16="","미기재",TEXT(B16,"yyyy-mm")) | D16: 10:56 | E16: Sport Chek (Yorkdale) | F16: Sport Chek | G16: 3401 Dufferin St, North York | H16: CAD | I16: -56.24 | J16: -7.31 | M16: -63.55 | N16: Mastercard | O16: Y | P16: 환불(RETURN) - 백팩 사이즈 교환 | Q16: IMG_5455.HEIC
A17: 12 | B17: 45906 | C17: =IF(B17="","미기재",TEXT(B17,"yyyy-mm")) | D17: 17:34 | E17: Uncle Tetsu (Yonge & Sheppard) | F17: Uncle Tetsu | G17: 4909 Yonge St, Toronto | H17: CAD | I17: 14.75 | J17: 0 | M17: 14.75 | N17: Mastercard | O17: Y | Q17: IMG_5530.HEIC
A18: 13 | B18: 45906 | C18: =IF(B18="","미기재",TEXT(B18,"yyyy-mm")) | D18: 17:41 | E18: 주차 (Alpha Control, 미터 742809) | F18: 주차 (Alpha Control, 미터 742809) | G18: 주소 미기재 | H18: CAD | M18: 1 | O18: Y | P18: 이메일 영수증 / 세금 내역 없음 | Q18: IMG_5607.HEIC
A19: 14 | B19: 45906 | C19: =IF(B19="","미기재",TEXT(B19,"yyyy-mm")) | D19: 18:45 | E19: Parksmart (주차, Mobile Permit) | F19: Parksmart (주차, Mobile Permit) | G19: 151 Beecroft Rd, Toronto | H19: CAD | M19: 4.37 | O19: Y | P19: 이메일 인보이스 / 세금 내역 없음 | Q19: IMG_5619.HEIC
A20: 15 | B20: 45909 | C20: =IF(B20="","미기재",TEXT(B20,"yyyy-mm")) | D20: 18:25 | E20: Staples (Grand Park) | F20: Staples | G20: 3950 Grand Park Dr, Mississauga | H20: CAD | I20: 2.58 | J20: 0.34 | M20: 2.92 | N20: Mastercard | O20: Y | P20: PC 대여 + 컬러 출력 | Q20: IMG_5615.HEIC
A21: 16 | B21: 45910 | C21: =IF(B21="","미기재",TEXT(B21,"yyyy-mm")) | D21: 17:34 | E21: Domino's Pizza #10482 | F21: Domino's Pizza | G21: 3843 Bloor St W, Etobicoke | H21: CAD | I21: 19 | J21: 2.47 | M21: 21.47 | N21: Visa | O21: Y | P21: 50% 피자 쿠폰 -18.98 적용 / 날짜는 카드전표(IMG_5521) 기준 | Q21: IMG_5522.HEIC
A22: 17 | B22: 45910 | C22: =IF(B22="","미기재",TEXT(B22,"yyyy-mm")) | D22: 18:00 | E22: Domino's Pizza #10482 | F22: Domino's Pizza | G22: 3843 Bloor St W, Etobicoke | H22: CAD | M22: 21.47 | N22: Visa | O22: N | P22: [중복] IMG_5522와 같은 거래의 카드전표 - 합계 제외 | Q22: IMG_5521.HEIC
A23: 18 | B23: 45913 | C23: =IF(B23="","미기재",TEXT(B23,"yyyy-mm")) | D23: 09:30 | E23: McDonald's (#1320) | F23: McDonald's | G23: 주소 미기재 | H23: CAD | I23: 16.59 | J23: 2.16 | M23: 18.75 | N23: Mastercard | O23: Y | P23: Two Can Dine 할인 -2.40 | Q23: IMG_5528.HEIC
A24: 19 | B24: 45913 | C24: =IF(B24="","미기재",TEXT(B24,"yyyy-mm")) | D24: 09:38 | E24: McDonald's (#1320) | F24: McDonald's | G24: 주소 미기재 | H24: CAD | I24: 12.06 | J24: 1.57 | M24: 13.63 | N24: Mastercard | O24: Y | P24: Two Can Dine 할인 -3.60 | Q24: IMG_5529.HEIC
A25: 20 | B25: 45913 | C25: =IF(B25="","미기재",TEXT(B25,"yyyy-mm")) | D25: 10:36 | E25: Costco Gas (#1655) | F25: Costco 주유소 | G25: 2260 Islington Ave, Etobicoke | H25: CAD | I25: 63.13 | J25: 8.21 | M25: 71.34 | N25: Mastercard | O25: Y | P25: 주유 52.114L (HST 포함가) | Q25: IMG_5543.HEIC
A26: 21 | B26: 45914 | C26: =IF(B26="","미기재",TEXT(B26,"yyyy-mm")) | D26: 18:08 | E26: Tim Hortons | F26: Tim Hortons | G26: 415 The Westway, Etobicoke | H26: CAD | I26: 9.99 | J26: 0 | M26: 9.99 | N26: Mastercard | O26: Y | Q26: IMG_5542.HEIC
A27: 22 | B27: 45916 | C27: =IF(B27="","미기재",TEXT(B27,"yyyy-mm")) | E27: Costco.ca 온라인 주문 | F27: Costco.ca (온라인) | G27: 온라인 (Order #1224456138) | H27: CAD | I27: 1299.99 | J27: 169 | M27: 1468.99 | N27: Mastercard | O27: Y | P27: Bayside 7피스 식탁세트 / 배송지 Mississauga | Q27: IMG_5620.HEIC
A28: 23 | B28: 45916 | C28: =IF(B28="","미기재",TEXT(B28,"yyyy-mm")) | D28: 18:16 | E28: Machi Machi (Eaton Centre) | F28: Machi Machi (Eaton Centre) | G28: 220 Yonge St, Toronto | H28: CAD | I28: 7.9 | J28: 1.03 | M28: 8.93 | N28: Debit | O28: Y | P28: 소계 15.80에서 직원할인 -7.90 적용 | Q28: IMG_5520.HEIC
A29: 24 | B29: 45920 | C29: =IF(B29="","미기재",TEXT(B29,"yyyy-mm")) | D29: 19:52 | E29: Tim Hortons | F29: Tim Hortons | G29: 415 The Westway, Etobicoke | H29: CAD | I29: 9.99 | J29: 0 | M29: 9.99 | N29: Mastercard | O29: Y | Q29: IMG_5540.HEIC
A30: 25 | B30: 45922 | C30: =IF(B30="","미기재",TEXT(B30,"yyyy-mm")) | D30: 06:45 | E30: Etobicoke Olympium (FitnessTO) | F30: Etobicoke Olympium (FitnessTO) | G30: 590 Rathburn Rd, Toronto | H30: CAD | I30: 219.88 | J30: 28.58 | M30: 248.46 | N30: Visa | O30: Y | P30: 멤버십(영수증 일부 가려짐) | Q30: IMG_5592.HEIC
A31: 26 | B31: 45922 | C31: =IF(B31="","미기재",TEXT(B31,"yyyy-mm")) | D31: 15:20 | E31: Uncle Tetsu (Yonge & Sheppard) | F31: Uncle Tetsu | G31: 4909 Yonge St, Toronto | H31: CAD | I31: 14.75 | J31: 0 | M31: 14.75 | N31: Mastercard | O31: Y | P31: 영수증+카드전표 한 장에 촬영 | Q31: IMG_5525.HEIC
A32: 27 | B32: 45922 | C32: =IF(B32="","미기재",TEXT(B32,"yyyy-mm")) | D32: 18:08 | E32: Kin-Kin Bakery & Bubble Tea | F32: Kin Kin Bakery | G32: Yonge-Sheppard Centre (4841 Yonge St), Toronto | H32: CAD | I32: 18.99 | J32: 0 | M32: 18.99 | N32: Mastercard | O32: Y | P32: 주문서엔 Cash 표기, 같은 시각 카드전표(IMG_5526)로 결제 확인 | Q32: IMG_5524.HEIC
A33: 28 | B33: 45922 | C33: =IF(B33="","미기재",TEXT(B33,"yyyy-mm")) | D33: 18:08 | E33: Kin Kin Bakery | F33: Kin Kin Bakery | G33: 4841 Yonge St, Toronto | H33: CAD | M33: 18.99 | N33: Mastercard | O33: N | P33: [중복] IMG_5524와 같은 거래의 카드전표 - 합계 제외 | Q33: IMG_5526.HEIC
A34: 29 | B34: 45924 | C34: =IF(B34="","미기재",TEXT(B34,"yyyy-mm")) | D34: 14:54 | E34: Tim Hortons | F34: Tim Hortons | G34: 1327 Dundas St E, Mississauga | H34: CAD | I34: 3.66 | J34: 0.18 | M34: 3.84 | N34: Mastercard | O34: Y | Q34: IMG_5523.HEIC
A35: 30 | B35: 45925 | C35: =IF(B35="","미기재",TEXT(B35,"yyyy-mm")) | D35: 19:09 | E35: Woojoo | F35: Woojoo | G35: 417 Bloor St W, Toronto | H35: CAD | I35: 44.95 | J35: 5.84 | M35: 50.79 | N35: Cash | O35: Y | P35: 10% 할인 -5.00 적용 | Q35: IMG_5527.HEIC
A36: 31 | B36: 45926 | C36: =IF(B36="","미기재",TEXT(B36,"yyyy-mm")) | D36: 12:16 | E36: Duct Cleaning & HVAC | F36: Duct Cleaning & HVAC | G36: Toronto (M1J 3E7) | H36: CAD | L36: 56.5 | M36: 621.5 | N36: Mastercard | O36: Y | P36: 카드전표만(세금 내역 없음) / 금액 565.00 + 팁 56.50 | Q36: IMG_5535.HEIC
A37: 32 | B37: 45929 | C37: =IF(B37="","미기재",TEXT(B37,"yyyy-mm")) | D37: 16:16 | E37: Copyright Copy Centre | F37: Copyright Copy Centre | G37: 215 Carlingview Dr, Etobicoke | H37: CAD | M37: 4 | N37: Mastercard | O37: Y | P37: 카드전표만(세금 내역 없음) | Q37: IMG_5546.HEIC
A38: 33 | B38: 45932 | C38: =IF(B38="","미기재",TEXT(B38,"yyyy-mm")) | D38: 09:40 | E38: Kin-Kin Bakery & Bubble Tea | F38: Kin Kin Bakery | G38: Yonge-Sheppard Centre (4841 Yonge St), Toronto | H38: CAD | I38: 25.98 | J38: 0 | M38: 25.98 | N38: Mastercard | O38: Y | P38: 주문서엔 Cash 표기, 같은 시각 카드전표(IMG_5548)로 결제 확인 | Q38: IMG_5549.HEIC
A39: 34 | B39: 45932 | C39: =IF(B39="","미기재",TEXT(B39,"yyyy-mm")) | D39: 09:42 | E39: Kin Kin Bakery | F39: Kin Kin Bakery | G39: 4841 Yonge St, Toronto | H39: CAD | M39: 25.98 | N39: Mastercard | O39: N | P39: [중복] IMG_5549와 같은 거래의 카드전표 - 합계 제외 | Q39: IMG_5548.HEIC
A40: 35 | B40: 45933 | C40: =IF(B40="","미기재",TEXT(B40,"yyyy-mm")) | D40: 22:05 | E40: ENZI Ice Cream | F40: ENZI Ice Cream | G40: 5317 Yonge St, Toronto | H40: CAD | I40: 12.4 | J40: 1.61 | M40: 14.01 | N40: Mastercard | O40: Y | Q40: IMG_5550.HEIC
...

Sheet 월별 요약
A1: 월별 지출 요약 (CAD, 합계반영=Y)
A3: 연월 | B3: 건수 | C3: 소계(세전) | D3: HST | E3: 기타세금 | F3: 팁 | G3: 합계
A4: 2025-01 | B4: =COUNTIFS('영수증 내역'!$O$6:$O$164,"Y",'영수증 내역'!$H$6:$H$164,"CAD",'영수증 내역'!$C$6:$C$164,$A4) | C4: =SUMIFS('영수증 내역'!$I$6:$I$164,'영수증 내역'!$O$6:$O$164,"Y",'영수증 내역'!$H$6:$H$164,"CAD",'영수증 내역'!$C$6:$C$164,$A4) | D4: =SUMIFS('영수증 내역'!$J$6:$J$164,'영수증 내역'!$O$6:$O$164,"Y",'영수증 내역'!$H$6:$H$164,"CAD",'영수증 내역'!$C$6:$C$164,$A4) | E4: =SUMIFS('영수증 내역'!$K$6:$K$164,'영수증 내역'!$O$6:$O$164,"Y",'영수증 내역'!$H$6:$H$164,"CAD",'영수증 내역'!$C$6:$C$164,$A4) | F4: =SUMIFS('영수증 내역'!$L$6:$L$164,'영수증 내역'!$O$6:$O$164,"Y",'영수증 내역'!$H$6:$H$164,"CAD",'영수증 내역'!$C$6:$C$164,$A4) | G4: =SUMIFS('영수증 내역'!$M$6:$M$164,'영수증 내역'!$O$6:$O$164,"Y",'영수증 내역'!$H$6:$H$164,"CAD",'영수증 내역'!$C$6:$C$164,$A4)
A5: 2025-07 | B5: =COUNTIFS('영수증 내역'!$O$6:$O$164,"Y",'영수증 내역'!$H$6:$H$164,"CAD",'영수증 내역'!$C$6:$C$164,$A5) | C5: =SUMIFS('영수증 내역'!$I$6:$I$164,'영수증 내역'!$O$6:$O$164,"Y",'영수증 내역'!$H$6:$H$164,"CAD",'영수증 내역'!$C$6:$C$164,$A5) | D5: =SUMIFS('영수증 내역'!$J$6:$J$164,'영수증 내역'!$O$6:$O$164,"Y",'영수증 내역'!$H$6:$H$164,"CAD",'영수증 내역'!$C$6:$C$164,$A5) | E5: =SUMIFS('영수증 내역'!$K$6:$K$164,'영수증 내역'!$O$6:$O$164,"Y",'영수증 내역'!$H$6:$H$164,"CAD",'영수증 내역'!$C$6:$C$164,$A5) | F5: =SUMIFS('영수증 내역'!$L$6:$L$164,'영수증 내역'!$O$6:$O$164,"Y",'영수증 내역'!$H$6:$H$164,"CAD",'영수증 내역'!$C$6:$C$164,$A5) | G5: =SUMIFS('영수증 내역'!$M$6:$M$164,'영수증 내역'!$O$6:$O$164,"Y",'영수증 내역'!$H$6:$H$164,"CAD",'영수증 내역'!$C$6:$C$164,$A5)
A6: 2025-08 | B6: =COUNTIFS('영수증 내역'!$O$6:$O$164,"Y",'영수증 내역'!$H$6:$H$164,"CAD",'영수증 내역'!$C$6:$C$164,$A6) | C6: =SUMIFS('영수증 내역'!$I$6:$I$164,'영수증 내역'!$O$6:$O$164,"Y",'영수증 내역'!$H$6:$H$164,"CAD",'영수증 내역'!$C$6:$C$164,$A6) | D6: =SUMIFS('영수증 내역'!$J$6:$J$164,'영수증 내역'!$O$6:$O$164,"Y",'영수증 내역'!$H$6:$H$164,"CAD",'영수증 내역'!$C$6:$C$164,$A6) | E6: =SUMIFS('영수증 내역'!$K$6:$K$164,'영수증 내역'!$O$6:$O$164,"Y",'영수증 내역'!$H$6:$H$164,"CAD",'영수증 내역'!$C$6:$C$164,$A6) | F6: =SUMIFS('영수증 내역'!$L$6:$L$164,'영수증 내역'!$O$6:$O$164,"Y",'영수증 내역'!$H$6:$H$164,"CAD",'영수증 내역'!$C$6:$C$164,$A6) | G6: =SUMIFS('영수증 내역'!$M$6:$M$164,'영수증 내역'!$O$6:$O$164,"Y",'영수증 내역'!$H$6:$H$164,"CAD",'영수증 내역'!$C$6:$C$164,$A6)
A7: 2025-09 | B7: =COUNTIFS('영수증 내역'!$O$6:$O$164,"Y",'영수증 내역'!$H$6:$H$164,"CAD",'영수증 내역'!$C$6:$C$164,$A7) | C7: =SUMIFS('영수증 내역'!$I$6:$I$164,'영수증 내역'!$O$6:$O$164,"Y",'영수증 내역'!$H$6:$H$164,"CAD",'영수증 내역'!$C$6:$C$164,$A7) | D7: =SUMIFS('영수증 내역'!$J$6:$J$164,'영수증 내역'!$O$6:$O$164,"Y",'영수증 내역'!$H$6:$H$164,"CAD",'영수증 내역'!$C$6:$C$164,$A7) | E7: =SUMIFS('영수증 내역'!$K$6:$K$164,'영수증 내역'!$O$6:$O$164,"Y",'영수증 내역'!$H$6:$H$164,"CAD",'영수증 내역'!$C$6:$C$164,$A7) | F7: =SUMIFS('영수증 내역'!$L$6:$L$164,'영수증 내역'!$O$6:$O$164,"Y",'영수증 내역'!$H$6:$H$164,"CAD",'영수증 내역'!$C$6:$C$164,$A7) | G7: =SUMIFS('영수증 내역'!$M$6:$M$164,'영수증 내역'!$O$6:$O$164,"Y",'영수증 내역'!$H$6:$H$164,"CAD",'영수증 내역'!$C$6:$C$164,$A7)
A8: 2025-10 | B8: =COUNTIFS('영수증 내역'!$O$6:$O$164,"Y",'영수증 내역'!$H$6:$H$164,"CAD",'영수증 내역'!$C$6:$C$164,$A8) | C8: =SUMIFS('영수증 내역'!$I$6:$I$164,'영수증 내역'!$O$6:$O$164,"Y",'영수증 내역'!$H$6:$H$164,"CAD",'영수증 내역'!$C$6:$C$164,$A8) | D8: =SUMIFS('영수증 내역'!$J$6:$J$164,'영수증 내역'!$O$6:$O$164,"Y",'영수증 내역'!$H$6:$H$164,"CAD",'영수증 내역'!$C$6:$C$164,$A8) | E8: =SUMIFS('영수증 내역'!$K$6:$K$164,'영수증 내역'!$O$6:$O$164,"Y",'영수증 내역'!$H$6:$H$164,"CAD",'영수증 내역'!$C$6:$C$164,$A8) | F8: =SUMIFS('영수증 내역'!$L$6:$L$164,'영수증 내역'!$O$6:$O$164,"Y",'영수증 내역'!$H$6:$H$164,"CAD",'영수증 내역'!$C$6:$C$164,$A8) | G8: =SUMIFS('영수증 내역'!$M$6:$M$164,'영수증 내역'!$O$6:$O$164,"Y",'영수증 내역'!$H$6:$H$164,"CAD",'영수증 내역'!$C$6:$C$164,$A8)
A9: 2025-11 | B9: =COUNTIFS('영수증 내역'!$O$6:$O$164,"Y",'영수증 내역'!$H$6:$H$164,"CAD",'영수증 내역'!$C$6:$C$164,$A9) | C9: =SUMIFS('영수증 내역'!$I$6:$I$164,'영수증 내역'!$O$6:$O$164,"Y",'영수증 내역'!$H$6:$H$164,"CAD",'영수증 내역'!$C$6:$C$164,$A9) | D9: =SUMIFS('영수증 내역'!$J$6:$J$164,'영수증 내역'!$O$6:$O$164,"Y",'영수증 내역'!$H$6:$H$164,"CAD",'영수증 내역'!$C$6:$C$164,$A9) | E9: =SUMIFS('영수증 내역'!$K$6:$K$164,'영수증 내역'!$O$6:$O$164,"Y",'영수증 내역'!$H$6:$H$164,"CAD",'영수증 내역'!$C$6:$C$164,$A9) | F9: =SUMIFS('영수증 내역'!$L$6:$L$164,'영수증 내역'!$O$6:$O$164,"Y",'영수증 내역'!$H$6:$H$164,"CAD",'영수증 내역'!$C$6:$C$164,$A9) | G9: =SUMIFS('영수증 내역'!$M$6:$M$164,'영수증 내역'!$O$6:$O$164,"Y",'영수증 내역'!$H$6:$H$164,"CAD",'영수증 내역'!$C$6:$C$164,$A9)
A10: 2025-12 | B10: =COUNTIFS('영수증 내역'!$O$6:$O$164,"Y",'영수증 내역'!$H$6:$H$164,"CAD",'영수증 내역'!$C$6:$C$164,$A10) | C10: =SUMIFS('영수증 내역'!$I$6:$I$164,'영수증 내역'!$O$6:$O$164,"Y",'영수증 내역'!$H$6:$H$164,"CAD",'영수증 내역'!$C$6:$C$164,$A10) | D10: =SUMIFS('영수증 내역'!$J$6:$J$164,'영수증 내역'!$O$6:$O$164,"Y",'영수증 내역'!$H$6:$H$164,"CAD",'영수증 내역'!$C$6:$C$164,$A10) | E10: =SUMIFS('영수증 내역'!$K$6:$K$164,'영수증 내역'!$O$6:$O$164,"Y",'영수증 내역'!$H$6:$H$164,"CAD",'영수증 내역'!$C$6:$C$164,$A10) | F10: =SUMIFS('영수증 내역'!$L$6:$L$164,'영수증 내역'!$O$6:$O$164,"Y",'영수증 내역'!$H$6:$H$164,"CAD",'영수증 내역'!$C$6:$C$164,$A10) | G10: =SUMIFS('영수증 내역'!$M$6:$M$164,'영수증 내역'!$O$6:$O$164,"Y",'영수증 내역'!$H$6:$H$164,"CAD",'영수증 내역'!$C$6:$C$164,$A10)
A11: 2026-01 | B11: =COUNTIFS('영수증 내역'!$O$6:$O$164,"Y",'영수증 내역'!$H$6:$H$164,"CAD",'영수증 내역'!$C$6:$C$164,$A11) | C11: =SUMIFS('영수증 내역'!$I$6:$I$164,'영수증 내역'!$O$6:$O$164,"Y",'영수증 내역'!$H$6:$H$164,"CAD",'영수증 내역'!$C$6:$C$164,$A11) | D11: =SUMIFS('영수증 내역'!$J$6:$J$164,'영수증 내역'!$O$6:$O$164,"Y",'영수증 내역'!$H$6:$H$164,"CAD",'영수증 내역'!$C$6:$C$164,$A11) | E11: =SUMIFS('영수증 내역'!$K$6:$K$164,'영수증 내역'!$O$6:$O$164,"Y",'영수증 내역'!$H$6:$H$164,"CAD",'영수증 내역'!$C$6:$C$164,$A11) | F11: =SUMIFS('영수증 내역'!$L$6:$L$164,'영수증 내역'!$O$6:$O$164,"Y",'영수증 내역'!$H$6:$H$164,"CAD",'영수증 내역'!$C$6:$C$164,$A11) | G11: =SUMIFS('영수증 내역'!$M$6:$M$164,'영수증 내역'!$O$6:$O$164,"Y",'영수증 내역'!$H$6:$H$164,"CAD",'영수증 내역'!$C$6:$C$164,$A11)
A12: 2026-02 | B12: =COUNTIFS('영수증 내역'!$O$6:$O$164,"Y",'영수증 내역'!$H$6:$H$164,"CAD",'영수증 내역'!$C$6:$C$164,$A12) | C12: =SUMIFS('영수증 내역'!$I$6:$I$164,'영수증 내역'!$O$6:$O$164,"Y",'영수증 내역'!$H$6:$H$164,"CAD",'영수증 내역'!$C$6:$C$164,$A12) | D12: =SUMIFS('영수증 내역'!$J$6:$J$164,'영수증 내역'!$O$6:$O$164,"Y",'영수증 내역'!$H$6:$H$164,"CAD",'영수증 내역'!$C$6:$C$164,$A12) | E12: =SUMIFS('영수증 내역'!$K$6:$K$164,'영수증 내역'!$O$6:$O$164,"Y",'영수증 내역'!$H$6:$H$164,"CAD",'영수증 내역'!$C$6:$C$164,$A12) | F12: =SUMIFS('영수증 내역'!$L$6:$L$164,'영수증 내역'!$O$6:$O$164,"Y",'영수증 내역'!$H$6:$H$164,"CAD",'영수증 내역'!$C$6:$C$164,$A12) | G12: =SUMIFS('영수증 내역'!$M$6:$M$164,'영수증 내역'!$O$6:$O$164,"Y",'영수증 내역'!$H$6:$H$164,"CAD",'영수증 내역'!$C$6:$C$164,$A12)
A13: 2026-03 | B13: =COUNTIFS('영수증 내역'!$O$6:$O$164,"Y",'영수증 내역'!$H$6:$H$164,"CAD",'영수증 내역'!$C$6:$C$164,$A13) | C13: =SUMIFS('영수증 내역'!$I$6:$I$164,'영수증 내역'!$O$6:$O$164,"Y",'영수증 내역'!$H$6:$H$164,"CAD",'영수증 내역'!$C$6:$C$164,$A13) | D13: =SUMIFS('영수증 내역'!$J$6:$J$164,'영수증 내역'!$O$6:$O$164,"Y",'영수증 내역'!$H$6:$H$164,"CAD",'영수증 내역'!$C$6:$C$164,$A13) | E13: =SUMIFS('영수증 내역'!$K$6:$K$164,'영수증 내역'!$O$6:$O$164,"Y",'영수증 내역'!$H$6:$H$164,"CAD",'영수증 내역'!$C$6:$C$164,$A13) | F13: =SUMIFS('영수증 내역'!$L$6:$L$164,'영수증 내역'!$O$6:$O$164,"Y",'영수증 내역'!$H$6:$H$164,"CAD",'영수증 내역'!$C$6:$C$164,$A13) | G13: =SUMIFS('영수증 내역'!$M$6:$M$164,'영수증 내역'!$O$6:$O$164,"Y",'영수증 내역'!$H$6:$H$164,"CAD",'영수증 내역'!$C$6:$C$164,$A13)
A14: 2026-04 | B14: =COUNTIFS('영수증 내역'!$O$6:$O$164,"Y",'영수증 내역'!$H$6:$H$164,"CAD",'영수증 내역'!$C$6:$C$164,$A14) | C14: =SUMIFS('영수증 내역'!$I$6:$I$164,'영수증 내역'!$O$6:$O$164,"Y",'영수증 내역'!$H$6:$H$164,"CAD",'영수증 내역'!$C$6:$C$164,$A14) | D14: =SUMIFS('영수증 내역'!$J$6:$J$164,'영수증 내역'!$O$6:$O$164,"Y",'영수증 내역'!$H$6:$H$164,"CAD",'영수증 내역'!$C$6:$C$164,$A14) | E14: =SUMIFS('영수증 내역'!$K$6:$K$164,'영수증 내역'!$O$6:$O$164,"Y",'영수증 내역'!$H$6:$H$164,"CAD",'영수증 내역'!$C$6:$C$164,$A14) | F14: =SUMIFS('영수증 내역'!$L$6:$L$164,'영수증 내역'!$O$6:$O$164,"Y",'영수증 내역'!$H$6:$H$164,"CAD",'영수증 내역'!$C$6:$C$164,$A14) | G14: =SUMIFS('영수증 내역'!$M$6:$M$164,'영수증 내역'!$O$6:$O$164,"Y",'영수증 내역'!$H$6:$H$164,"CAD",'영수증 내역'!$C$6:$C$164,$A14)
A15: 2026-05 | B15: =COUNTIFS('영수증 내역'!$O$6:$O$164,"Y",'영수증 내역'!$H$6:$H$164,"CAD",'영수증 내역'!$C$6:$C$164,$A15) | C15: =SUMIFS('영수증 내역'!$I$6:$I$164,'영수증 내역'!$O$6:$O$164,"Y",'영수증 내역'!$H$6:$H$164,"CAD",'영수증 내역'!$C$6:$C$164,$A15) | D15: =SUMIFS('영수증 내역'!$J$6:$J$164,'영수증 내역'!$O$6:$O$164,"Y",'영수증 내역'!$H$6:$H$164,"CAD",'영수증 내역'!$C$6:$C$164,$A15) | E15: =SUMIFS('영수증 내역'!$K$6:$K$164,'영수증 내역'!$O$6:$O$164,"Y",'영수증 내역'!$H$6:$H$164,"CAD",'영수증 내역'!$C$6:$C$164,$A15) | F15: =SUMIFS('영수증 내역'!$L$6:$L$164,'영수증 내역'!$O$6:$O$164,"Y",'영수증 내역'!$H$6:$H$164,"CAD",'영수증 내역'!$C$6:$C$164,$A15) | G15: =SUMIFS('영수증 내역'!$M$6:$M$164,'영수증 내역'!$O$6:$O$164,"Y",'영수증 내역'!$H$6:$H$164,"CAD",'영수증 내역'!$C$6:$C$164,$A15)
... A20: 미기재 | B20: =COUNTIFS('영수증 내역'!$O$6:$O$164,"Y",'영수증 내역'!$H$6:$H$164,"CAD",'영수증 내역'!$C$6:$C$164,$A20) | C20: =SUMIFS('영수증 내역'!$I$6:$I$164,'영수증 내역'!$O$6:$O$164,"Y",'영수증 내역'!$H$6:$H$164,"CAD",'영수증 내역'!$C$6:$C$164,$A20) | D20: =SUMIFS('영수증 내역'!$J$6:$J$164,'영수증 내역'!$O$6:$O$164,"Y",'영수증 내역'!$H$6:$H$164,"CAD",'영수증 내역'!$C$6:$C$164,$A20) | E20: =SUMIFS('영수증 내역'!$K$6:$K$164,'영수증 내역'!$O$6:$O$164,"Y",'영수증 내역'!$H$6:$H$164,"CAD",'영수증 내역'!$C$6:$C$164,$A20) | F20: =SUMIFS('영수증 내역'!$L$6:$L$164,'영수증 내역'!$O$6:$O$164,"Y",'영수증 내역'!$H$6:$H$164,"CAD",'영수증 내역'!$C$6:$C$164,$A20) | G20: =SUMIFS('영수증 내역'!$M$6:$M$164,'영수증 내역'!$O$6:$O$164,"Y",'영수증 내역'!$H$6:$H$164,"CAD",'영수증 내역'!$C$6:$C$164,$A20)
A21: 합계 | B21: =SUM(B4:B20) | C21: =SUM(C4:C20) | D21: =SUM(D4:D20) | E21: =SUM(E4:E20) | F21: =SUM(F4:F20) | G21: =SUM(G4:G20)
A23: ※ 미국 영수증(USD) 2건은 이 표에서 제외됨 → 구입처별 요약 하단 참고

Sheet 구입처별 요약
A1: 구입처별 지출 요약 (합계반영=Y, 합계 큰 순)
A3: 구입처 그룹 | B3: 통화 | C3: 건수 | D3: 소계(세전) | E3: HST | F3: 기타세금 | G3: 팁 | H3: 합계
A4: Costco.ca (온라인) | B4: CAD | C4: =COUNTIFS('영수증 내역'!$O$6:$O$164,"Y",'영수증 내역'!$F$6:$F$164,$A4,'영수증 내역'!$H$6:$H$164,$B4) | D4: =SUMIFS('영수증 내역'!$I$6:$I$164,'영수증 내역'!$O$6:$O$164,"Y",'영수증 내역'!$F$6:$F$164,$A4,'영수증 내역'!$H$6:$H$164,$B4) | E4: =SUMIFS('영수증 내역'!$J$6:$J$164,'영수증 내역'!$O$6:$O$164,"Y",'영수증 내역'!$F$6:$F$164,$A4,'영수증 내역'!$H$6:$H$164,$B4) | F4: =SUMIFS('영수증 내역'!$K$6:$K$164,'영수증 내역'!$O$6:$O$164,"Y",'영수증 내역'!$F$6:$F$164,$A4,'영수증 내역'!$H$6:$H$164,$B4) | G4: =SUMIFS('영수증 내역'!$L$6:$L$164,'영수증 내역'!$O$6:$O$164,"Y",'영수증 내역'!$F$6:$F$164,$A4,'영수증 내역'!$H$6:$H$164,$B4) | H4: =SUMIFS('영수증 내역'!$M$6:$M$164,'영수증 내역'!$O$6:$O$164,"Y",'영수증 내역'!$F$6:$F$164,$A4,'영수증 내역'!$H$6:$H$164,$B4)
A5: Home Depot | B5: CAD | C5: =COUNTIFS('영수증 내역'!$O$6:$O$164,"Y",'영수증 내역'!$F$6:$F$164,$A5,'영수증 내역'!$H$6:$H$164,$B5) | D5: =SUMIFS('영수증 내역'!$I$6:$I$164,'영수증 내역'!$O$6:$O$164,"Y",'영수증 내역'!$F$6:$F$164,$A5,'영수증 내역'!$H$6:$H$164,$B5) | E5: =SUMIFS('영수증 내역'!$J$6:$J$164,'영수증 내역'!$O$6:$O$164,"Y",'영수증 내역'!$F$6:$F$164,$A5,'영수증 내역'!$H$6:$H$164,$B5) | F5: =SUMIFS('영수증 내역'!$K$6:$K$164,'영수증 내역'!$O$6:$O$164,"Y",'영수증 내역'!$F$6:$F$164,$A5,'영수증 내역'!$H$6:$H$164,$B5) | G5: =SUMIFS('영수증 내역'!$L$6:$L$164,'영수증 내역'!$O$6:$O$164,"Y",'영수증 내역'!$F$6:$F$164,$A5,'영수증 내역'!$H$6:$H$164,$B5) | H5: =SUMIFS('영수증 내역'!$M$6:$M$164,'영수증 내역'!$O$6:$O$164,"Y",'영수증 내역'!$F$6:$F$164,$A5,'영수증 내역'!$H$6:$H$164,$B5)
A6: Mac Outpost | B6: CAD | C6: =COUNTIFS('영수증 내역'!$O$6:$O$164,"Y",'영수증 내역'!$F$6:$F$164,$A6,'영수증 내역'!$H$6:$H$164,$B6) | D6: =SUMIFS('영수증 내역'!$I$6:$I$164,'영수증 내역'!$O$6:$O$164,"Y",'영수증 내역'!$F$6:$F$164,$A6,'영수증 내역'!$H$6:$H$164,$B6) | E6: =SUMIFS('영수증 내역'!$J$6:$J$164,'영수증 내역'!$O$6:$O$164,"Y",'영수증 내역'!$F$6:$F$164,$A6,'영수증 내역'!$H$6:$H$164,$B6) | F6: =SUMIFS('영수증 내역'!$K$6:$K$164,'영수증 내역'!$O$6:$O$164,"Y",'영수증 내역'!$F$6:$F$164,$A6,'영수증 내역'!$H$6:$H$164,$B6) | G6: =SUMIFS('영수증 내역'!$L$6:$L$164,'영수증 내역'!$O$6:$O$164,"Y",'영수증 내역'!$F$6:$F$164,$A6,'영수증 내역'!$H$6:$H$164,$B6) | H6: =SUMIFS('영수증 내역'!$M$6:$M$164,'영수증 내역'!$O$6:$O$164,"Y",'영수증 내역'!$F$6:$F$164,$A6,'영수증 내역'!$H$6:$H$164,$B6)
A7: YSH CPA Professional Corporation | B7: CAD | C7: =COUNTIFS('영수증 내역'!$O$6:$O$164,"Y",'영수증 내역'!$F$6:$F$164,$A7,'영수증 내역'!$H$6:$H$164,$B7) | D7: =SUMIFS('영수증 내역'!$I$6:$I$164,'영수증 내역'!$O$6:$O$164,"Y",'영수증 내역'!$F$6:$F$164,$A7,'영수증 내역'!$H$6:$H$164,$B7) | E7: =SUMIFS('영수증 내역'!$J$6:$J$164,'영수증 내역'!$O$6:$O$164,"Y",'영수증 내역'!$F$6:$F$164,$A7,'영수증 내역'!$H$6:$H$164,$B7) | F7: =SUMIFS('영수증 내역'!$K$6:$K$164,'영수증 내역'!$O$6:$O$164,"Y",'영수증 내역'!$F$6:$F$164,$A7,'영수증 내역'!$H$6:$H$164,$B7) | G7: =SUMIFS('영수증 내역'!$L$6:$L$164,'영수증 내역'!$O$6:$O$164,"Y",'영수증 내역'!$F$6:$F$164,$A7,'영수증 내역'!$H$6:$H$164,$B7) | H7: =SUMIFS('영수증 내역'!$M$6:$M$164,'영수증 내역'!$O$6:$O$164,"Y",'영수증 내역'!$F$6:$F$164,$A7,'영수증 내역'!$H$6:$H$164,$B7)
A8: Costco 주유소 | B8: CAD | C8: =COUNTIFS('영수증 내역'!$O$6:$O$164,"Y",'영수증 내역'!$F$6:$F$164,$A8,'영수증 내역'!$H$6:$H$164,$B8) | D8: =SUMIFS('영수증 내역'!$I$6:$I$164,'영수증 내역'!$O$6:$O$164,"Y",'영수증 내역'!$F$6:$F$164,$A8,'영수증 내역'!$H$6:$H$164,$B8) | E8: =SUMIFS('영수증 내역'!$J$6:$J$164,'영수증 내역'!$O$6:$O$164,"Y",'영수증 내역'!$F$6:$F$164,$A8,'영수증 내역'!$H$6:$H$164,$B8) | F8: =SUMIFS('영수증 내역'!$K$6:$K$164,'영수증 내역'!$O$6:$O$164,"Y",'영수증 내역'!$F$6:$F$164,$A8,'영수증 내역'!$H$6:$H$164,$B8) | G8: =SUMIFS('영수증 내역'!$L$6:$L$164,'영수증 내역'!$O$6:$O$164,"Y",'영수증 내역'!$F$6:$F$164,$A8,'영수증 내역'!$H$6:$H$164,$B8) | H8: =SUMIFS('영수증 내역'!$M$6:$M$164,'영수증 내역'!$O$6:$O$164,"Y",'영수증 내역'!$F$6:$F$164,$A8,'영수증 내역'!$H$6:$H$164,$B8)
A9: Duct Cleaning & HVAC | B9: CAD | C9: =COUNTIFS('영수증 내역'!$O$6:$O$164,"Y",'영수증 내역'!$F$6:$F$164,$A9,'영수증 내역'!$H$6:$H$164,$B9) | D9: =SUMIFS('영수증 내역'!$I$6:$I$164,'영수증 내역'!$O$6:$O$164,"Y",'영수증 내역'!$F$6:$F$164,$A9,'영수증 내역'!$H$6:$H$164,$B9) | E9: =SUMIFS('영수증 내역'!$J$6:$J$164,'영수증 내역'!$O$6:$O$164,"Y",'영수증 내역'!$F$6:$F$164,$A9,'영수증 내역'!$H$6:$H$164,$B9) | F9: =SUMIFS('영수증 내역'!$K$6:$K$164,'영수증 내역'!$O$6:$O$164,"Y",'영수증 내역'!$F$6:$F$164,$A9,'영수증 내역'!$H$6:$H$164,$B9) | G9: =SUMIFS('영수증 내역'!$L$6:$L$164,'영수증 내역'!$O$6:$O$164,"Y",'영수증 내역'!$F$6:$F$164,$A9,'영수증 내역'!$H$6:$H$164,$B9) | H9: =SUMIFS('영수증 내역'!$M$6:$M$164,'영수증 내역'!$O$6:$O$164,"Y",'영수증 내역'!$F$6:$F$164,$A9,'영수증 내역'!$H$6:$H$164,$B9)
A10: RECO (Real Estate Council of Ontario) | B10: CAD | C10: =COUNTIFS('영수증 내역'!$O$6:$O$164,"Y",'영수증 내역'!$F$6:$F$164,$A10,'영수증 내역'!$H$6:$H$164,$B10) | D10: =SUMIFS('영수증 내역'!$I$6:$I$164,'영수증 내역'!$O$6:$O$164,"Y",'영수증 내역'!$F$6:$F$164,$A10,'영수증 내역'!$H$6:$H$164,$B10) | E10: =SUMIFS('영수증 내역'!$J$6:$J$164,'영수증 내역'!$O$6:$O$164,"Y",'영수증 내역'!$F$6:$F$164,$A10,'영수증 내역'!$H$6:$H$164,$B10) | F10: =SUMIFS('영수증 내역'!$K$6:$K$164,'영수증 내역'!$O$6:$O$164,"Y",'영수증 내역'!$F$6:$F$164,$A10,'영수증 내역'!$H$6:$H$164,$B10) | G10: =SUMIFS('영수증 내역'!$L$6:$L$164,'영수증 내역'!$O$6:$O$164,"Y",'영수증 내역'!$F$6:$F$164,$A10,'영수증 내역'!$H$6:$H$164,$B10) | H10: =SUMIFS('영수증 내역'!$M$6:$M$164,'영수증 내역'!$O$6:$O$164,"Y",'영수증 내역'!$F$6:$F$164,$A10,'영수증 내역'!$H$6:$H$164,$B10)
A11: Anthropic (Claude) | B11: CAD | C11: =COUNTIFS('영수증 내역'!$O$6:$O$164,"Y",'영수증 내역'!$F$6:$F$164,$A11,'영수증 내역'!$H$6:$H$164,$B11) | D11: =SUMIFS('영수증 내역'!$I$6:$I$164,'영수증 내역'!$O$6:$O$164,"Y",'영수증 내역'!$F$6:$F$164,$A11,'영수증 내역'!$H$6:$H$164,$B11) | E11: =SUMIFS('영수증 내역'!$J$6:$J$164,'영수증 내역'!$O$6:$O$164,"Y",'영수증 내역'!$F$6:$F$164,$A11,'영수증 내역'!$H$6:$H$164,$B11) | F11: =SUMIFS('영수증 내역'!$K$6:$K$164,'영수증 내역'!$O$6:$O$164,"Y",'영수증 내역'!$F$6:$F$164,$A11,'영수증 내역'!$H$6:$H$164,$B11) | G11: =SUMIFS('영수증 내역'!$L$6:$L$164,'영수증 내역'!$O$6:$O$164,"Y",'영수증 내역'!$F$6:$F$164,$A11,'영수증 내역'!$H$6:$H$164,$B11) | H11: =SUMIFS('영수증 내역'!$M$6:$M$164,'영수증 내역'!$O$6:$O$164,"Y",'영수증 내역'!$F$6:$F$164,$A11,'영수증 내역'!$H$6:$H$164,$B11)
A12: Etobicoke Olympium (FitnessTO) | B12: CAD | C12: =COUNTIFS('영수증 내역'!$O$6:$O$164,"Y",'영수증 내역'!$F$6:$F$164,$A12,'영수증 내역'!$H$6:$H$164,$B12) | D12: =SUMIFS('영수증 내역'!$I$6:$I$164,'영수증 내역'!$O$6:$O$164,"Y",'영수증 내역'!$F$6:$F$164,$A12,'영수증 내역'!$H$6:$H$164,$B12) | E12: =SUMIFS('영수증 내역'!$J$6:$J$164,'영수증 내역'!$O$6:$O$164,"Y",'영수증 내역'!$F$6:$F$164,$A12,'영수증 내역'!$H$6:$H$164,$B12) | F12: =SUMIFS('영수증 내역'!$K$6:$K$164,'영수증 내역'!$O$6:$O$164,"Y",'영수증 내역'!$F$6:$F$164,$A12,'영수증 내역'!$H$6:$H$164,$B12) | G12: =SUMIFS('영수증 내역'!$L$6:$L$164,'영수증 내역'!$O$6:$O$164,"Y",'영수증 내역'!$F$6:$F$164,$A12,'영수증 내역'!$H$6:$H$164,$B12) | H12: =SUMIFS('영수증 내역'!$M$6:$M$164,'영수증 내역'!$O$6:$O$164,"Y",'영수증 내역'!$F$6:$F$164,$A12,'영수증 내역'!$H$6:$H$164,$B12)
A13: ByteDance (CapCut Pro 연간 구독) | B13: CAD | C13: =COUNTIFS('영수증 내역'!$O$6:$O$164,"Y",'영수증 내역'!$F$6:$F$164,$A13,'영수증 내역'!$H$6:$H$164,$B13) | D13: =SUMIFS('영수증 내역'!$I$6:$I$164,'영수증 내역'!$O$6:$O$164,"Y",'영수증 내역'!$F$6:$F$164,$A13,'영수증 내역'!$H$6:$H$164,$B13) | E13: =SUMIFS('영수증 내역'!$J$6:$J$164,'영수증 내역'!$O$6:$O$164,"Y",'영수증 내역'!$F$6:$F$164,$A13,'영수증 내역'!$H$6:$H$164,$B13) | F13: =SUMIFS('영수증 내역'!$K$6:$K$164,'영수증 내역'!$O$6:$O$164,"Y",'영수증 내역'!$F$6:$F$164,$A13,'영수증 내역'!$H$6:$H$164,$B13) | G13: =SUMIFS('영수증 내역'!$L$6:$L$164,'영수증 내역'!$O$6:$O$164,"Y",'영수증 내역'!$F$6:$F$164,$A13,'영수증 내역'!$H$6:$H$164,$B13) | H13: =SUMIFS('영수증 내역'!$M$6:$M$164,'영수증 내역'!$O$6:$O$164,"Y",'영수증 내역'!$F$6:$F$164,$A13,'영수증 내역'!$H$6:$H$164,$B13)
A14: Sushi Legend | B14: CAD | C14: =COUNTIFS('영수증 내역'!$O$6:$O$164,"Y",'영수증 내역'!$F$6:$F$164,$A14,'영수증 내역'!$H$6:$H$164,$B14) | D14: =SUMIFS('영수증 내역'!$I$6:$I$164,'영수증 내역'!$O$6:$O$164,"Y",'영수증 내역'!$F$6:$F$164,$A14,'영수증 내역'!$H$6:$H$164,$B14) | E14: =SUMIFS('영수증 내역'!$J$6:$J$164,'영수증 내역'!$O$6:$O$164,"Y",'영수증 내역'!$F$6:$F$164,$A14,'영수증 내역'!$H$6:$H$164,$B14) | F14: =SUMIFS('영수증 내역'!$K$6:$K$164,'영수증 내역'!$O$6:$O$164,"Y",'영수증 내역'!$F$6:$F$164,$A14,'영수증 내역'!$H$6:$H$164,$B14) | G14: =SUMIFS('영수증 내역'!$L$6:$L$164,'영수증 내역'!$O$6:$O$164,"Y",'영수증 내역'!$F$6:$F$164,$A14,'영수증 내역'!$H$6:$H$164,$B14) | H14: =SUMIFS('영수증 내역'!$M$6:$M$164,'영수증 내역'!$O$6:$O$164,"Y",'영수증 내역'!$F$6:$F$164,$A14,'영수증 내역'!$H$6:$H$164,$B14)
A15: Jangteo Gukbap | B15: CAD | C15: =COUNTIFS('영수증 내역'!$O$6:$O$164,"Y",'영수증 내역'!$F$6:$F$164,$A15,'영수증 내역'!$H$6:$H$164,$B15) | D15: =SUMIFS('영수증 내역'!$I$6:$I$164,'영수증 내역'!$O$6:$O$164,"Y",'영수증 내역'!$F$6:$F$164,$A15,'영수증 내역'!$H$6:$H$164,$B15) | E15: =SUMIFS('영수증 내역'!$J$6:$J$164,'영수증 내역'!$O$6:$O$164,"Y",'영수증 내역'!$F$6:$F$164,$A15,'영수증 내역'!$H$6:$H$164,$B15) | F15: =SUMIFS('영수증 내역'!$K$6:$K$164,'영수증 내역'!$O$6:$O$164,"Y",'영수증 내역'!$F$6:$F$164,$A15,'영수증 내역'!$H$6:$H$164,$B15) | G15: =SUMIFS('영수증 내역'!$L$6:$L$164,'영수증 내역'!$O$6:$O$164,"Y",'영수증 내역'!$F$6:$F$164,$A15,'영수증 내역'!$H$6:$H$164,$B15) | H15: =SUMIFS('영수증 내역'!$M$6:$M$164,'영수증 내역'!$O$6:$O$164,"Y",'영수증 내역'!$F$6:$F$164,$A15,'영수증 내역'!$H$6:$H$164,$B15)
... A79: Dunkin' (LaGuardia 공항, 미국) | B79: USD | C79: =COUNTIFS('영수증 내역'!$O$6:$O$164,"Y",'영수증 내역'!$F$6:$F$164,$A79,'영수증 내역'!$H$6:$H$164,$B79) | D79: =SUMIFS('영수증 내역'!$I$6:$I$164,'영수증 내역'!$O$6:$O$164,"Y",'영수증 내역'!$F$6:$F$164,$A79,'영수증 내역'!$H$6:$H$164,$B79) | E79: =SUMIFS('영수증 내역'!$J$6:$J$164,'영수증 내역'!$O$6:$O$164,"Y",'영수증 내역'!$F$6:$F$164,$A79,'영수증 내역'!$H$6:$H$164,$B79) | F79: =SUMIFS('영수증 내역'!$K$6:$K$164,'영수증 내역'!$O$6:$O$164,"Y",'영수증 내역'!$F$6:$F$164,$A79,'영수증 내역'!$H$6:$H$164,$B79) | G79: =SUMIFS('영수증 내역'!$L$6:$L$164,'영수증 내역'!$O$6:$O$164,"Y",'영수증 내역'!$F$6:$F$164,$A79,'영수증 내역'!$H$6:$H$164,$B79) | H79: =SUMIFS('영수증 내역'!$M$6:$M$164,'영수증 내역'!$O$6:$O$164,"Y",'영수증 내역'!$F$6:$F$164,$A79,'영수증 내역'!$H$6:$H$164,$B79)
A80: 합계 (CAD) | C80: =SUMIFS(C4:C79,B4:B79,"CAD") | D80: =SUMIFS(D4:D79,$B$4:$B$79,"CAD") | E80: =SUMIFS(E4:E79,$B$4:$B$79,"CAD") | F80: =SUMIFS(F4:F79,$B$4:$B$79,"CAD") | G80: =SUMIFS(G4:G79,$B$4:$B$79,"CAD") | H80: =SUMIFS(H4:H79,$B$4:$B$79,"CAD")

Sheet 안내
A1: 안내
A3: 대상 | B3: Google Drive 폴더의 영수증 사진 159장 (HEIC). 동일 사진 2장(IMG_5338)은 1건으로 처리 → 158장, 한 장에 2건이 적힌 Noki 영수증은 2행으로 분리
A4: 합계반영 = N | B4: 같은 거래의 카드전표·2페이지 등 중복 사진 (8행). 목록엔 남겨 두고 합계에서만 제외
A5: HST 빈칸 | B5: 카드전표만 있거나 영수증에 세금이 따로 표기되지 않은 건 (금액은 총액만 기록)
A6: HST 0.00 | B6: 비과세 품목 (예: Timbits 50개, 처방약, 일부 베이커리/식품, 기프트코드)
A7: 주유 영수증 | B7: 주유는 HST 포함가. 영수증의 "HST Included" 금액을 HST로, 총액-HST를 소계로 기록
A8: 기타세금 | B8: HST가 아닌 세금: RECO 보험료 PST 8% (34.48), 미국 판매세 2건
A9: USD | B9: 미국(뉴욕) 영수증 2건은 달러(USD) 그대로 기록, CAD 합계에서 제외
A10: 환불 | B10: Sport Chek 반품 2건(2025-09-06, 2026-01-23)과 Hollister 환불 1건은 음수(-)로 기록 → 합계에서 차감
A11: 추정/확인 필요 | B11: IMG_5473 상호 미기재(A&W로 추정) · IMG_5575 LCBO 날짜 미기재, HST 역산 · IMG_5613 맥북은 주문확인서(결제 대기) · IMG_5625 CPA 인보이스(결제 영수증 아님) · IMG_5627 사진 흐림 · IMG_5351 Chick-fil-A 날짜 01/11/2025 (1월 11일 또는 11월 1일)
A12: 날짜 해석 | B12: 미국식(MM/DD) 표기 영수증은 영수증 종류별로 해석. 예: ServiceOntario 09-04-2026 → 2026-09-04, Home Depot 02/09/25 → 2025-09-02 (DD/MM)
